Workbook

Sheet Transactions
A1: Date | B1: Month | C1: Type | D1: Category | E1: Subcategory | F1: Amount | G1: Notes
A2: 2024-08-01 | B2: August | C2: Expense | D2: Food | F2: 3000
A3: 2024-08-01 | B3: August | C3: Expense | D3: Rent | F3: 6000
A4: 2024-08-01 | B4: August | C4: Expense | D4: House Stuff | F4: 2000 | G4: asso. Stuff to 1 & 2
A5: 2024-08-01 | B5: August | C5: Expense | D5: Transport | F5: 1680
A6: 2024-08-01 | B6: August | C6: Expense | D6: Family & Friends | F6: 1300
A7: 2024-08-01 | B7: August | C7: Expense | D7: Personal | E7: Mistake to GF | F7: 1270
A8: 2024-08-01 | B8: August | C8: Expense | D8: Personal | E8: Gifts to GF | F8: 460
A9: 2024-08-01 | B9: August | C9: Expense | D9: Airtime/Data | F9: 400
A10: 2024-08-01 | B10: August | C10: Income | D10: Salary | F10: 20000
A11: 2024-08-01 | B11: August | C11: Income | D11: From Family | F11: 500
A12: 2024-08-01 | B12: August | C12: Savings | D12: Savings | E12: August Salary | F12: 5000 | G12: To MMF
A13: 2024-09-01 | B13: September | C13: Expense | D13: Food | E13: Unga 4kg | F13: 280
A14: 2024-09-01 | B14: September | C14: Expense | D14: Food | E14: Mala | F14: 200
A15: 2024-09-01 | B15: September | C15: Expense | D15: Food | E15: Cooking Oil | F15: 305
A16: 2024-09-01 | B16: September | C16: Expense | D16: Food | E16: Onions | F16: 150
A17: 2024-09-01 | B17: September | C17: Expense | D17: Food | E17: Tomatoes | F17: 330
A18: 2024-09-01 | B18: September | C18: Expense | D18: Food | E18: Saumu | F18: 50
A19: 2024-09-01 | B19: September | C19: Expense | D19: Food | E19: Bananas | F19: 150
A20: 2024-09-01 | B20: September | C20: Expense | D20: Food | E20: Kamande | F20: 865 | G20: #3
A21: 2024-09-01 | B21: September | C21: Expense | D21: Food | E21: Eggs | F21: 300
A22: 2024-09-01 | B22: September | C22: Expense | D22: Food | E22: Coffee | F22: 114
A23: 2024-09-01 | B23: September | C23: Expense | D23: Food | E23: Fruits[apples] | F23: 100
A24: 2024-09-01 | B24: September | C24: Expense | D24: Food | E24: Avocado | F24: 135
A25: 2024-09-01 | B25: September | C25: Expense | D25: Food | E25: Potatoes | F25: 250
A26: 2024-09-01 | B26: September | C26: Expense | D26: Food | E26: Milk | F26: 150
A27: 2024-09-01 | B27: September | C27: Expense | D27: Food | E27: Hoho | F27: 20
A28: 2024-09-01 | B28: September | C28: Expense | D28: Food | E28: Meat | F28: 150 | G28: #frid 12
A29: 2024-09-01 | B29: September | C29: Expense | D29: Food | E29: Carrots | F29: 70
A30: 2024-09-01 | B30: September | C30: Expense | D30: Food | E30: Coriadale | F30: 20
A31: 2024-09-01 | B31: September | C31: Expense | D31: Food | E31: Veges | F31: 110
A32: 2024-09-01 | B32: September | C32: Expense | D32: Food | E32: Oranges | F32: 50
A33: 2024-09-01 | B33: September | C33: Expense | D33: Food | E33: Tangawizi and Saumu | F33: 40
A34: 2024-09-01 | B34: September | C34: Expense | D34: Food | E34: Ripe Bananas | F34: 60
A35: 2024-09-01 | B35: September | C35: Expense | D35: Food | E35: Coffee | F35: 250 | G35: #2
A36: 2024-09-01 | B36: September | C36: Expense | D36: Food | E36: Peanuts | F36: 230
A37: 2024-09-01 | B37: September | C37: Expense | D37: Eat Outs | E37: Yummy Hotel | F37: 150
A38: 2024-09-01 | B38: September | C38: Expense | D38: Eat Outs | E38: Café | F38: 80
A39: 2024-09-01 | B39: September | C39: Expense | D39: Eat Outs | E39: Smk | F39: 40
A40: 2024-09-01 | B40: September | C40: Expense | D40: Eat Outs | E40: Lunch 9th | F40: 120
...

Sheet Budget
A1: Category | B1: Budgeted | C1: Actual | D1: Variance
A2: Food | B2: 0 | C2: =SUMIF(Transactions!D:D, A2, Transactions!F:F) -> 10071 | D2: =B2-C2 -> -10071
A3: Rent | B3: 0 | C3: =SUMIF(Transactions!D:D, A3, Transactions!F:F) -> 24400 | D3: =B3-C3 -> -24400
A4: House Stuff | B4: 0 | C4: =SUMIF(Transactions!D:D, A4, Transactions!F:F) -> 4966 | D4: =B4-C4 -> -4966
A5: Transport | B5: 0 | C5: =SUMIF(Transactions!D:D, A5, Transactions!F:F) -> 3130 | D5: =B5-C5 -> -3130
A6: Family & Friends | B6: 0 | C6: =SUMIF(Transactions!D:D, A6, Transactions!F:F) -> 10370 | D6: =B6-C6 -> -10370
A7: Personal | B7: 0 | C7: =SUMIF(Transactions!D:D, A7, Transactions!F:F) -> 1730 | D7: =B7-C7 -> -1730
A8: Airtime/Data | B8: 0 | C8: =SUMIF(Transactions!D:D, A8, Transactions!F:F) -> 1030 | D8: =B8-C8 -> -1030
A9: Eat Outs | B9: 0 | C9: =SUMIF(Transactions!D:D, A9, Transactions!F:F) -> 880 | D9: =B9-C9 -> -880
A10: License | B10: 0 | C10: =SUMIF(Transactions!D:D, A10, Transactions!F:F) -> 750 | D10: =B10-C10 -> -750
A11: Other | B11: 0 | C11: =SUMIF(Transactions!D:D, A11, Transactions!F:F) -> 0 | D11: =B11-C11 -> 0
A12: Total | B12: =SUM(B2:B11) -> 0 | C12: =SUM(C2:C11) -> 57327 | D12: =SUM(D2:D11) -> -57327

Sheet Monthly Summary
A1: Month | B1: Total Income | C1: Total Expenses | D1: Net | E1: Savings Contribution
A2: August | B2: =SUMIFS(Transactions!F:F, Transactions!B:B, A2, Transactions!C:C, "Income") -> 20500 | C2: =SUMIFS(Transactions!F:F, Transactions!B:B, A2, Transactions!C:C, "Expense") -> 16110 | D2: =B2-C2 -> 4390 | E2: =SUMIFS(Transactions!F:F, Transactions!B:B, A2, Transactions!C:C, "Savings") -> 5000
A3: September | B3: =SUMIFS(Transactions!F:F, Transactions!B:B, A3, Transactions!C:C, "Income") -> 37550 | C3: =SUMIFS(Transactions!F:F, Transactions!B:B, A3, Transactions!C:C, "Expense") -> 33657 | D3: =B3-C3 -> 3893 | E3: =SUMIFS(Transactions!F:F, Transactions!B:B, A3, Transactions!C:C, "Savings") -> 19700
A4: October | B4: =SUMIFS(Transactions!F:F, Transactions!B:B, A4, Transactions!C:C, "Income") -> 21200 | C4: =SUMIFS(Transactions!F:F, Transactions!B:B, A4, Transactions!C:C, "Expense") -> 12897 | D4: =B4-C4 -> 8303 | E4: =SUMIFS(Transactions!F:F, Transactions!B:B, A4, Transactions!C:C, "Savings") -> 26950
A5: November | B5: =SUMIFS(Transactions!F:F, Transactions!B:B, A5, Transactions!C:C, "Income") -> 21923 | C5: =SUMIFS(Transactions!F:F, Transactions!B:B, A5, Transactions!C:C, "Expense") -> 10663 | D5: =B5-C5 -> 11260 | E5: =SUMIFS(Transactions!F:F, Transactions!B:B, A5, Transactions!C:C, "Savings") -> 34450

Sheet Savings & Investments
A1: Date | B1: Description | C1: Contribution | D1: Return Rate (%) | E1: Projected Return | F1: Balance
A2: 2024-08-01 | B2: M-Pesa MMF August | C2: 5000 | D2: 5 | E2: =C2 * (D2/100) / 12 -> 20.833333 | F2: =C2 + E2 -> 5020.8333
A3: 2024-09-01 | B3: M-Pesa MMF September | C3: 7500 | D3: 5 | E3: =C3 * (D3/100) / 12 -> 31.25 | F3: =F2 + C3 + E3 -> 12552.083
A4: 2024-10-01 | B4: M-Pesa MMF October | C4: 7500 | D4: 5 | E4: =C4 * (D4/100) / 12 -> 31.25 | F4: =F3 + C4 + E4 -> 20083.333
A5: 2024-11-01 | B5: M-Pesa MMF November | C5: 7500 | D5: 5 | E5: =C5 * (D5/100) / 12 -> 31.25 | F5: =F4 + C5 + E5 -> 27614.583
A6: 2025-11-02 | B6: Switch to Gulfcap MMF (12.9% p.a.) | C6: 0 | D6: 12.9 | F6: =F5 + C6 + E6 -> 27614.583
A7: 2025-11-02 | B7: Treasury Bills (10%+) | C7: 0 | D7: 10 | F7: =F6 + C7 + E7 -> 27614.583
A8: 2025-11-02 | B8: SACCO Account (8-10%) | C8: 0 | D8: 9 | F8: =F7 + C8 + E8 -> 27614.583
A10: Notes: Upgrade from 4-6% M-Pesa to higher yield options like MMFs (up to 13%), T-Bills, SACCOs for better returns. Research and diversify.

Sheet Goals
A1: Goal | B1: Cost | C1: Status | D1: Deadline | E1: Funded | F1: Remaining
A2: Pay for License | B2: 750 | C2: Done | E2: 750 | F2: =B2-E2 -> 0
A3: Buy Lamp Light | B3: 2400 | C3: Done | E3: 2400 | F3: =B3-E3 -> 0
A4: Study/Computer Table | B4: 7000 | C4: Done | E4: 7000 | F4: =B4-E4 -> 0
A5: Monitor | B5: 30000 | C5: Pending | D5: 2025-01-01 | E5: 0 | F5: =B5-E5 -> 30000
A6: Chair | B6: 8500 | C6: Pending | D6: 2025-02-01 | E6: 0 | F6: =B6-E6 -> 8500
A7: Keyboard | B7: 3000 | C7: Pending | D7: 2025-03-01 | E7: 0 | F7: =B7-E7 -> 3000
A8: Powerful Laptop | B8: 100000 | C8: Pending | D8: 2025-03-01 | E8: 0 | F8: =B8-E8 -> 100000
A9: Get 4 Certifications | B9: 0 | C9: Pending | D9: 2025-12-31 | E9: 0 | F9: =B9-E9 -> 0
